2024-09-27T12:50:28.318967+00:00 app[web.1]: File "/app/.heroku/python/lib/python3.12/site-packages/gunicorn/app/wsgiapp.py", line 47, in load_wsgiapp
2024-09-27T12:50:28.318967+00:00 app[web.1]: return util.import_app(self.app_uri)
2024-09-27T12:50:28.318967+00:00 app[web.1]: ^^^^^^^^^^^^^^^^^^^^^^^^^^^^^
2024-09-27T12:50:28.318967+00:00 app[web.1]: File "/app/.heroku/python/lib/python3.12/site-packages/gunicorn/util.py", line 370, in import_app
2024-09-27T12:50:28.318967+00:00 app[web.1]: mod = importlib.import_module(module)
2024-09-27T12:50:28.318968+00:00 app[web.1]: ^^^^^^^^^^^^^^^^^^^^^^^^^^^^^^^
2024-09-27T12:50:28.318969+00:00 app[web.1]: File "/app/.heroku/python/lib/python3.12/importlib/__init__.py", line 90, in import_module
2024-09-27T12:50:28.318970+00:00 app[web.1]: return _bootstrap._gcd_import(name[level:], package, level)
2024-09-27T12:50:28.318970+00:00 app[web.1]: ^^^^^^^^^^^^^^^^^^^^^^^^^^^^^^^^^^^^^^^^^^^^^^^^^^^^
2024-09-27T12:50:28.318970+00:00 app[web.1]: File "<frozen importlib._bootstrap>", line 1387, in _gcd_import
2024-09-27T12:50:28.318971+00:00 app[web.1]: File "<frozen importlib._bootstrap>", line 1360, in _find_and_load
2024-09-27T12:50:28.318971+00:00 app[web.1]: File "<frozen importlib._bootstrap>", line 1331, in _find_and_load_unlocked
2024-09-27T12:50:28.318971+00:00 app[web.1]: File "<frozen importlib._bootstrap>", line 935, in _load_unlocked
2024-09-27T12:50:28.318971+00:00 app[web.1]: File "<frozen importlib._bootstrap_external>", line 995, in exec_module
2024-09-27T12:50:28.318971+00:00 app[web.1]: File "<frozen importlib._bootstrap>", line 488, in _call_with_frames_removed
2024-09-27T12:50:28.318971+00:00 app[web.1]: File "/app/app/run.py", line 47, in <module>
2024-09-27T12:50:28.318971+00:00 app[web.1]: shutil.copyfile(bundled_db_path, db_path)
2024-09-27T12:50:28.318972+00:00 app[web.1]: File "/app/.heroku/python/lib/python3.12/shutil.py", line 260, in copyfile
2024-09-27T12:50:28.318972+00:00 app[web.1]: with open(src, 'rb') as fsrc:
2024-09-27T12:50:28.318972+00:00 app[web.1]: ^^^^^^^^^^^^^^^
2024-09-27T12:50:28.318972+00:00 app[web.1]: FileNotFoundError: [Errno 2] No such file or directory: '../data/DisasterResponse.db'
2024-09-27T12:50:28.318972+00:00 app[web.1]: [2024-09-27 12:50:28 +0000] [9] [ERROR] Exception in worker process
2024-09-27T12:50:28.318973+00:00 app[web.1]: Traceback (most recent call last):
2024-09-27T12:50:28.318973+00:00 app[web.1]: File "/app/.heroku/python/lib/python3.12/site-packages/gunicorn/arbiter.py", line 608, in spawn_worker
2024-09-27T12:50:28.318973+00:00 app[web.1]: worker.init_process()
2024-09-27T12:50:28.318973+00:00 app[web.1]: File "/app/.heroku/python/lib/python3.12/site-packages/gunicorn/workers/base.py", line 135, in init_process
2024-09-27T12:50:28.318973+00:00 app[web.1]: self.load_wsgi()
2024-09-27T12:50:28.318973+00:00 app[web.1]: File "/app/.heroku/python/lib/python3.12/site-packages/gunicorn/workers/base.py", line 147, in load_wsgi
2024-09-27T12:50:28.318973+00:00 app[web.1]: self.wsgi = self.app.wsgi()
2024-09-27T12:50:28.318974+00:00 app[web.1]: ^^^^^^^^^^^^^^^
2024-09-27T12:50:28.318974+00:00 app[web.1]: File "/app/.heroku/python/lib/python3.12/site-packages/gunicorn/app/base.py", line 66, in wsgi
2024-09-27T12:50:28.318974+00:00 app[web.1]: self.callable = self.load()
2024-09-27T12:50:28.318974+00:00 app[web.1]: ^^^^^^^^^^^
2024-09-27T12:50:28.318974+00:00 app[web.1]: File "/app/.heroku/python/lib/python3.12/site-packages/gunicorn/app/wsgiapp.py", line 57, in load
2024-09-27T12:50:28.318974+00:00 app[web.1]: return self.load_wsgiapp()
2024-09-27T12:50:28.318975+00:00 app[web.1]: ^^^^^^^^^^^^^^^^^^^
2024-09-27T12:50:28.318975+00:00 app[web.1]: File "/app/.heroku/python/lib/python3.12/site-packages/gunicorn/app/wsgiapp.py", line 47, in load_wsgiapp
2024-09-27T12:50:28.318975+00:00 app[web.1]: return util.import_app(self.app_uri)
2024-09-27T12:50:28.318975+00:00 app[web.1]: ^^^^^^^^^^^^^^^^^^^^^^^^^^^^^
2024-09-27T12:50:28.318975+00:00 app[web.1]: File "/app/.heroku/python/lib/python3.12/site-packages/gunicorn/util.py", line 370, in import_app
2024-09-27T12:50:28.318976+00:00 app[web.1]: mod = importlib.import_module(module)
2024-09-27T12:50:28.318976+00:00 app[web.1]: ^^^^^^^^^^^^^^^^^^^^^^^^^^^^^^^
2024-09-27T12:50:28.318976+00:00 app[web.1]: File "/app/.heroku/python/lib/python3.12/importlib/__init__.py", line 90, in import_module
2024-09-27T12:50:28.318977+00:00 app[web.1]: return _bootstrap._gcd_import(name[level:], package, level)
2024-09-27T12:50:28.318977+00:00 app[web.1]: ^^^^^^^^^^^^^^^^^^^^^^^^^^^^^^^^^^^^^^^^^^^^^^^^^^^^
2024-09-27T12:50:28.318977+00:00 app[web.1]: File "<frozen importlib._bootstrap>", line 1387, in _gcd_import
2024-09-27T12:50:28.318977+00:00 app[web.1]: File "<frozen importlib._bootstrap>", line 1360, in _find_and_load
2024-09-27T12:50:28.318977+00:00 app[web.1]: File "<frozen importlib._bootstrap>", line 1331, in _find_and_load_unlocked
2024-09-27T12:50:28.318977+00:00 app[web.1]: File "<frozen importlib._bootstrap>", line 935, in _load_unlocked
2024-09-27T12:50:28.318978+00:00 app[web.1]: File "<frozen importlib._bootstrap_external>", line 995, in exec_module
2024-09-27T12:50:28.318978+00:00 app[web.1]: File "<frozen importlib._bootstrap>", line 488, in _call_with_frames_removed
2024-09-27T12:50:28.318982+00:00 app[web.1]: File "/app/app/run.py", line 47, in <module>
2024-09-27T12:50:28.318983+00:00 app[web.1]: shutil.copyfile(bundled_db_path, db_path)
2024-09-27T12:50:28.318983+00:00 app[web.1]: File "/app/.heroku/python/lib/python3.12/shutil.py", line 260, in copyfile
2024-09-27T12:50:28.318983+00:00 app[web.1]: with open(src, 'rb') as fsrc:
2024-09-27T12:50:28.318983+00:00 app[web.1]: ^^^^^^^^^^^^^^^
2024-09-27T12:50:28.318983+00:00 app[web.1]: FileNotFoundError: [Errno 2] No such file or directory: '../data/DisasterResponse.db'
2024-09-27T12:50:28.319064+00:00 app[web.1]: [2024-09-27 12:50:28 +0000] [9] [INFO] Worker exiting (pid: 9)
2024-09-27T12:50:28.319068+00:00 app[web.1]: [2024-09-27 12:50:28 +0000] [10] [INFO] Worker exiting (pid: 10)
2024-09-27T12:50:28.531558+00:00 app[web.1]: [2024-09-27 12:50:28 +0000] [2] [ERROR] Worker (pid:9) exited with code 3
2024-09-27T12:50:28.534515+00:00 app[web.1]: [2024-09-27 12:50:28 +0000] [2] [ERROR] Worker (pid:10) exited with code 3
2024-09-27T12:50:28.534570+00:00 app[web.1]: Traceback (most recent call last):
2024-09-27T12:50:28.534582+00:00 app[web.1]: File "/app/.heroku/python/lib/python3.12/site-packages/gunicorn/arbiter.py", line 208, in run
2024-09-27T12:50:28.534764+00:00 app[web.1]: self.sleep()
2024-09-27T12:50:28.534797+00:00 app[web.1]: File "/app/.heroku/python/lib/python3.12/site-packages/gunicorn/arbiter.py", line 359, in sleep
2024-09-27T12:50:28.534890+00:00 app[web.1]: ready = select.select([self.PIPE[0]], [], [], 1.0)
2024-09-27T12:50:28.534973+00:00 app[web.1]: ^^^^^^^^^^^^^^^^^^^^^^^^^^^^^^^^^^^^^^^^^^
2024-09-27T12:50:28.534982+00:00 app[web.1]: File "/app/.heroku/python/lib/python3.12/site-packages/gunicorn/arbiter.py", line 241, in handle_chld
2024-09-27T12:50:28.535035+00:00 app[web.1]: self.reap_workers()
2024-09-27T12:50:28.535052+00:00 app[web.1]: File "/app/.heroku/python/lib/python3.12/site-packages/gunicorn/arbiter.py", line 529, in reap_workers
2024-09-27T12:50:28.535187+00:00 app[web.1]: raise HaltServer(reason, self.WORKER_BOOT_ERROR)
2024-09-27T12:50:28.535232+00:00 app[web.1]: gunicorn.errors.HaltServer: <HaltServer 'Worker failed to boot.' 3>
2024-09-27T12:50:28.535240+00:00 app[web.1]: 
2024-09-27T12:50:28.535241+00:00 app[web.1]: During handling of the above exception, another exception occurred:
2024-09-27T12:50:28.535249+00:00 app[web.1]: 
2024-09-27T12:50:28.535250+00:00 app[web.1]: Traceback (most recent call last):
2024-09-27T12:50:28.535261+00:00 app[web.1]: File "/app/.heroku/python/bin/gunicorn", line 8, in <module>
2024-09-27T12:50:28.535311+00:00 app[web.1]: sys.exit(run())
2024-09-27T12:50:28.535397+00:00 app[web.1]: ^^^^^
2024-09-27T12:50:28.535399+00:00 app[web.1]: File "/app/.heroku/python/lib/python3.12/site-packages/gunicorn/app/wsgiapp.py", line 66, in run
2024-09-27T12:50:28.535466+00:00 app[web.1]: WSGIApplication("%(prog)s [OPTIONS] [APP_MODULE]", prog=prog).run()
2024-09-27T12:50:28.535493+00:00 app[web.1]: File "/app/.heroku/python/lib/python3.12/site-packages/gunicorn/app/base.py", line 235, in run
2024-09-27T12:50:28.535554+00:00 app[web.1]: super().run()
2024-09-27T12:50:28.535571+00:00 app[web.1]: File "/app/.heroku/python/lib/python3.12/site-packages/gunicorn/app/base.py", line 71, in run
2024-09-27T12:50:28.535604+00:00 app[web.1]: Arbiter(self).run()
2024-09-27T12:50:28.535624+00:00 app[web.1]: File "/app/.heroku/python/lib/python3.12/site-packages/gunicorn/arbiter.py", line 228, in run
2024-09-27T12:50:28.535674+00:00 app[web.1]: self.halt(reason=inst.reason, exit_status=inst.exit_status)
2024-09-27T12:50:28.535699+00:00 app[web.1]: File "/app/.heroku/python/lib/python3.12/site-packages/gunicorn/arbiter.py", line 341, in halt
2024-09-27T12:50:28.535766+00:00 app[web.1]: self.stop()
2024-09-27T12:50:28.535780+00:00 app[web.1]: File "/app/.heroku/python/lib/python3.12/site-packages/gunicorn/arbiter.py", line 395, in stop
2024-09-27T12:50:28.535849+00:00 app[web.1]: time.sleep(0.1)
2024-09-27T12:50:28.535871+00:00 app[web.1]: File "/app/.heroku/python/lib/python3.12/site-packages/gunicorn/arbiter.py", line 241, in handle_chld
2024-09-27T12:50:28.535916+00:00 app[web.1]: self.reap_workers()
2024-09-27T12:50:28.535927+00:00 app[web.1]: File "/app/.heroku/python/lib/python3.12/site-packages/gunicorn/arbiter.py", line 529, in reap_workers
2024-09-27T12:50:28.536017+00:00 app[web.1]: raise HaltServer(reason, self.WORKER_BOOT_ERROR)
2024-09-27T12:50:28.536042+00:00 app[web.1]: gunicorn.errors.HaltServer: <HaltServer 'Worker failed to boot.' 3>
2024-09-27T12:50:28.590131+00:00 heroku[web.1]: Process exited with status 1
2024-09-27T12:50:28.612421+00:00 heroku[web.1]: State changed from up to crashed
2024-09-27T12:55:01.188650+00:00 heroku[router]: at=error code=H10 desc="App crashed" method=GET path="/" host=disaster-response-app-be215b66c206.herokuapp.com request_id=9315de7f-57b7-405f-99ef-1106c2e625db fwd="80.142.214.23" dyno= connect= service= status=503 bytes= protocol=https
2024-09-27T12:55:17.547751+00:00 heroku[router]: at=error code=H10 desc="App crashed" method=GET path="/" host=disaster-response-app-be215b66c206.herokuapp.com request_id=3baa792e-6e44-442f-af3d-eaf63d2d49e3 fwd="80.142.214.23" dyno= connect= service= status=503 bytes= protocol=https
